# chatGPT 分析报告
## 接下来请你逐文件分析下面的工程[0/10] 请对下面的程序文件做一个概述: D:\MOSS\finetune_moss.py
# openLMLab moss


## [1/10] 请对下面的程序文件做一个概述: D:\MOSS\moss_cli_demo.py

该程序文件为一个使用 HuggingFace Transformers 库实现的基于模型 MOSS 的对话系统。其中程序通过加载已经保存在 HuggingFace 模型库中的 MOSS 模型，并对用户输入的信息进行处理，产生相应的回答。程序的主要功能为自然语言处理并实现回答。程序包含了一些针对对话质量和用户体验的限制条件，例如对 MOSS 的回答内容限制为积极、礼貌、有趣和有参与感，且禁止与相应提示、指令或规则相关的事物进行讨论。此外，程序还包含了一些未开启的功能，如Web搜索、计算器等。

## [2/10] 请对下面的程序文件做一个概述: D:\MOSS\moss_gui_demo.py

该程序为一个基于 Transformers 模型和 Gradio 库实现的聊天机器人，预测输入的文本并生成相应的回复。程序中使用了 GPU 加速，以及对超参数（如最大长度、Top P、温度等）的调整。同时，程序也对输入文本进行了一定的处理，包括将 Markdown 文本转换为 HTML，将不支持的文本进行处理等。 该程序还可以通过 Gradio 进行展示，并提供了清除历史记录等功能。

## [3/10] 请对下面的程序文件做一个概述: D:\MOSS\moss_inference.py

[Local Message] 警告，线程3在执行过程中遭遇问题, Traceback：

```
Traceback (most recent call last):
  File ".\crazy_functions\crazy_utils.py", line 201, in _req_gpt
    gpt_say = predict_no_ui_long_connection(
              ^^^^^^^^^^^^^^^^^^^^^^^^^^^^^^
  File ".\request_llm\bridge_all.py", line 173, in predict_no_ui_long_connection
    return method(inputs, llm_kwargs, history, sys_prompt, observe_window, console_slience)
           ^^^^^^^^^^^^^^^^^^^^^^^^^^^^^^^^^^^^^^^^^^^^^^^^^^^^^^^^^^^^^^^^^^^^^^^^^^^^^^^^
  File ".\request_llm\bridge_chatgpt.py", line 87, in predict_no_ui_long_connection
    raise RuntimeError("OpenAI拒绝了请求：" + error_msg)
RuntimeError: OpenAI拒绝了请求：{    "error": {        "message": "You exceeded your current quota, please check your plan and billing details.",        "type": "insufficient_quota",        "param": null,        "code": null    }}
```

[Local Message] 警告，线程3在执行过程中遭遇问题, Traceback：

```
Traceback (most recent call last):
  File ".\crazy_functions\crazy_utils.py", line 201, in _req_gpt
    gpt_say = predict_no_ui_long_connection(
              ^^^^^^^^^^^^^^^^^^^^^^^^^^^^^^
  File ".\request_llm\bridge_all.py", line 173, in predict_no_ui_long_connection
    return method(inputs, llm_kwargs, history, sys_prompt, observe_window, console_slience)
           ^^^^^^^^^^^^^^^^^^^^^^^^^^^^^^^^^^^^^^^^^^^^^^^^^^^^^^^^^^^^^^^^^^^^^^^^^^^^^^^^
  File ".\request_llm\bridge_chatgpt.py", line 87, in predict_no_ui_long_connection
    raise RuntimeError("OpenAI拒绝了请求：" + error_msg)
RuntimeError: OpenAI拒绝了请求：{    "error": {        "message": "You exceeded your current quota, please check your plan and billing details.",        "type": "insufficient_quota",        "param": null,        "code": null    }}
```

[Local Message] 警告，线程3在执行过程中遭遇问题, Traceback：

```
Traceback (most recent call last):
  File ".\crazy_functions\crazy_utils.py", line 201, in _req_gpt
    gpt_say = predict_no_ui_long_connection(
              ^^^^^^^^^^^^^^^^^^^^^^^^^^^^^^
  File ".\request_llm\bridge_all.py", line 173, in predict_no_ui_long_connection
    return method(inputs, llm_kwargs, history, sys_prompt, observe_window, console_slience)
           ^^^^^^^^^^^^^^^^^^^^^^^^^^^^^^^^^^^^^^^^^^^^^^^^^^^^^^^^^^^^^^^^^^^^^^^^^^^^^^^^
  File ".\request_llm\bridge_chatgpt.py", line 87, in predict_no_ui_long_connection
    raise RuntimeError("OpenAI拒绝了请求：" + error_msg)
RuntimeError: OpenAI拒绝了请求：{    "error": {        "message": "You exceeded your current quota, please check your plan and billing details.",        "type": "insufficient_quota",        "param": null,        "code": null    }}
```



## [4/10] 请对下面的程序文件做一个概述: D:\MOSS\utils.py

[Local Message] 警告，线程4在执行过程中遭遇问题, Traceback：

```
Traceback (most recent call last):
  File ".\crazy_functions\crazy_utils.py", line 201, in _req_gpt
    gpt_say = predict_no_ui_long_connection(
              ^^^^^^^^^^^^^^^^^^^^^^^^^^^^^^
  File ".\request_llm\bridge_all.py", line 173, in predict_no_ui_long_connection
    return method(inputs, llm_kwargs, history, sys_prompt, observe_window, console_slience)
           ^^^^^^^^^^^^^^^^^^^^^^^^^^^^^^^^^^^^^^^^^^^^^^^^^^^^^^^^^^^^^^^^^^^^^^^^^^^^^^^^
  File ".\request_llm\bridge_chatgpt.py", line 87, in predict_no_ui_long_connection
    raise RuntimeError("OpenAI拒绝了请求：" + error_msg)
RuntimeError: OpenAI拒绝了请求：{    "error": {        "message": "You exceeded your current quota, please check your plan and billing details.",        "type": "insufficient_quota",        "param": null,        "code": null    }}
```

[Local Message] 警告，线程4在执行过程中遭遇问题, Traceback：

```
Traceback (most recent call last):
  File ".\crazy_functions\crazy_utils.py", line 201, in _req_gpt
    gpt_say = predict_no_ui_long_connection(
              ^^^^^^^^^^^^^^^^^^^^^^^^^^^^^^
  File ".\request_llm\bridge_all.py", line 173, in predict_no_ui_long_connection
    return method(inputs, llm_kwargs, history, sys_prompt, observe_window, console_slience)
           ^^^^^^^^^^^^^^^^^^^^^^^^^^^^^^^^^^^^^^^^^^^^^^^^^^^^^^^^^^^^^^^^^^^^^^^^^^^^^^^^
  File ".\request_llm\bridge_chatgpt.py", line 87, in predict_no_ui_long_connection
    raise RuntimeError("OpenAI拒绝了请求：" + error_msg)
RuntimeError: OpenAI拒绝了请求：{    "error": {        "message": "You exceeded your current quota, please check your plan and billing details.",        "type": "insufficient_quota",        "param": null,        "code": null    }}
```

[Local Message] 警告，线程4在执行过程中遭遇问题, Traceback：

```
Traceback (most recent call last):
  File ".\crazy_functions\crazy_utils.py", line 201, in _req_gpt
    gpt_say = predict_no_ui_long_connection(
              ^^^^^^^^^^^^^^^^^^^^^^^^^^^^^^
  File ".\request_llm\bridge_all.py", line 173, in predict_no_ui_long_connection
    return method(inputs, llm_kwargs, history, sys_prompt, observe_window, console_slience)
           ^^^^^^^^^^^^^^^^^^^^^^^^^^^^^^^^^^^^^^^^^^^^^^^^^^^^^^^^^^^^^^^^^^^^^^^^^^^^^^^^
  File ".\request_llm\bridge_chatgpt.py", line 87, in predict_no_ui_long_connection
    raise RuntimeError("OpenAI拒绝了请求：" + error_msg)
RuntimeError: OpenAI拒绝了请求：{    "error": {        "message": "Rate limit reached for default-gpt-3.5-turbo in organization org-AuKGyhKmlQ3EbEATMDtOoiNY on requests per min. Limit: 3 / min. Please try again in 20s. Contact support@openai.com if you continue to have issues. Please add a payment method to your account to increase your rate limit. Visit https://platform.openai.com/account/billing to add a payment method.",        "type": "requests",        "param": null,        "code": null    }}
```



## [5/10] 请对下面的程序文件做一个概述: D:\MOSS\models\configuration_moss.py

该文件是一个包含了Moss模型配置信息的Python类，用于实例化一个Moss模型并定义其网络结构。它继承自`PretrainedConfig`类，并提供了一些可选的参数，如单词表大小、最大序列长度、嵌入层和隐藏层的维度、注意力头数、内层前馈层的维度等。此外，它还可以控制模型的输出，并提供了一些默认配置信息。

## [6/10] 请对下面的程序文件做一个概述: D:\MOSS\models\custom_autotune.py

这个程序文件实现了自动调优功能，针对Triton的自动调优，但是进行了一些修改。其中使用了40次而不是100次以进行调优。文件定义了一个Autotuner类，提供了多个参数，包括需要调优的函数、参数名称、配置列表、缓存键、重置为零等。文件还提供了autotune装饰器，可用于自动进行调优。

## [7/10] 请对下面的程序文件做一个概述: D:\MOSS\models\modeling_moss.py

[Local Message] 警告，线程7在执行过程中遭遇问题, Traceback：

```
Traceback (most recent call last):
  File ".\crazy_functions\crazy_utils.py", line 201, in _req_gpt
    gpt_say = predict_no_ui_long_connection(
              ^^^^^^^^^^^^^^^^^^^^^^^^^^^^^^
  File ".\request_llm\bridge_all.py", line 173, in predict_no_ui_long_connection
    return method(inputs, llm_kwargs, history, sys_prompt, observe_window, console_slience)
           ^^^^^^^^^^^^^^^^^^^^^^^^^^^^^^^^^^^^^^^^^^^^^^^^^^^^^^^^^^^^^^^^^^^^^^^^^^^^^^^^
  File ".\request_llm\bridge_chatgpt.py", line 87, in predict_no_ui_long_connection
    raise RuntimeError("OpenAI拒绝了请求：" + error_msg)
RuntimeError: OpenAI拒绝了请求：{    "error": {        "message": "Rate limit reached for default-gpt-3.5-turbo in organization org-AuKGyhKmlQ3EbEATMDtOoiNY on requests per min. Limit: 3 / min. Please try again in 20s. Contact support@openai.com if you continue to have issues. Please add a payment method to your account to increase your rate limit. Visit https://platform.openai.com/account/billing to add a payment method.",        "type": "requests",        "param": null,        "code": null    }}
```

[Local Message] 警告，文本过长将进行截断，Token溢出数：3600。

[Local Message] 警告，线程7在执行过程中遭遇问题, Traceback：

```
Traceback (most recent call last):
  File "E:\ana\envs\gptac_venv\Lib\site-packages\urllib3\connectionpool.py", line 449, in _make_request
    six.raise_from(e, None)
  File "<string>", line 3, in raise_from
  File "E:\ana\envs\gptac_venv\Lib\site-packages\urllib3\connectionpool.py", line 444, in _make_request
    httplib_response = conn.getresponse()
                       ^^^^^^^^^^^^^^^^^^
  File "E:\ana\envs\gptac_venv\Lib\http\client.py", line 1375, in getresponse
    response.begin()
  File "E:\ana\envs\gptac_venv\Lib\http\client.py", line 318, in begin
    version, status, reason = self._read_status()
                              ^^^^^^^^^^^^^^^^^^^
  File "E:\ana\envs\gptac_venv\Lib\http\client.py", line 279, in _read_status
    line = str(self.fp.readline(_MAXLINE + 1), "iso-8859-1")
               ^^^^^^^^^^^^^^^^^^^^^^^^^^^^^^
  File "E:\ana\envs\gptac_venv\Lib\socket.py", line 706, in readinto
    return self._sock.recv_into(b)
           ^^^^^^^^^^^^^^^^^^^^^^^
  File "E:\ana\envs\gptac_venv\Lib\ssl.py", line 1278, in recv_into
    return self.read(nbytes, buffer)
           ^^^^^^^^^^^^^^^^^^^^^^^^^
  File "E:\ana\envs\gptac_venv\Lib\ssl.py", line 1134, in read
    return self._sslobj.read(len, buffer)
           ^^^^^^^^^^^^^^^^^^^^^^^^^^^^^^
TimeoutError: The read operation timed out

During handling of the above exception, another exception occurred:

Traceback (most recent call last):
  File "E:\ana\envs\gptac_venv\Lib\site-packages\requests\adapters.py", line 489, in send
    resp = conn.urlopen(
           ^^^^^^^^^^^^^
  File "E:\ana\envs\gptac_venv\Lib\site-packages\urllib3\connectionpool.py", line 787, in urlopen
    retries = retries.increment(
              ^^^^^^^^^^^^^^^^^^
  File "E:\ana\envs\gptac_venv\Lib\site-packages\urllib3\util\retry.py", line 550, in increment
    raise six.reraise(type(error), error, _stacktrace)
          ^^^^^^^^^^^^^^^^^^^^^^^^^^^^^^^^^^^^^^^^^^^^
  File "E:\ana\envs\gptac_venv\Lib\site-packages\urllib3\packages\six.py", line 770, in reraise
    raise value
  File "E:\ana\envs\gptac_venv\Lib\site-packages\urllib3\connectionpool.py", line 703, in urlopen
    httplib_response = self._make_request(
                       ^^^^^^^^^^^^^^^^^^^
  File "E:\ana\envs\gptac_venv\Lib\site-packages\urllib3\connectionpool.py", line 451, in _make_request
    self._raise_timeout(err=e, url=url, timeout_value=read_timeout)
  File "E:\ana\envs\gptac_venv\Lib\site-packages\urllib3\connectionpool.py", line 340, in _raise_timeout
    raise ReadTimeoutError(
urllib3.exceptions.ReadTimeoutError: SOCKSHTTPSConnectionPool(host='api.openai.com', port=443): Read timed out. (read timeout=30)

During handling of the above exception, another exception occurred:

Traceback (most recent call last):
  File ".\request_llm\bridge_chatgpt.py", line 65, in predict_no_ui_long_connection
    response = requests.post(endpoint, headers=headers, proxies=proxies,
               ^^^^^^^^^^^^^^^^^^^^^^^^^^^^^^^^^^^^^^^^^^^^^^^^^^^^^^^^^
  File "E:\ana\envs\gptac_venv\Lib\site-packages\requests\api.py", line 115, in post
    return request("post", url, data=data, json=json, **kwargs)
           ^^^^^^^^^^^^^^^^^^^^^^^^^^^^^^^^^^^^^^^^^^^^^^^^^^^^
  File "E:\ana\envs\gptac_venv\Lib\site-packages\requests\api.py", line 59, in request
    return session.request(method=method, url=url, **kwargs)
           ^^^^^^^^^^^^^^^^^^^^^^^^^^^^^^^^^^^^^^^^^^^^^^^^^
  File "E:\ana\envs\gptac_venv\Lib\site-packages\requests\sessions.py", line 587, in request
    resp = self.send(prep, **send_kwargs)
           ^^^^^^^^^^^^^^^^^^^^^^^^^^^^^^
  File "E:\ana\envs\gptac_venv\Lib\site-packages\requests\sessions.py", line 701, in send
    r = adapter.send(request, **kwargs)
        ^^^^^^^^^^^^^^^^^^^^^^^^^^^^^^^
  File "E:\ana\envs\gptac_venv\Lib\site-packages\requests\adapters.py", line 578, in send
    raise ReadTimeout(e, request=request)
requests.exceptions.ReadTimeout: SOCKSHTTPSConnectionPool(host='api.openai.com', port=443): Read timed out. (read timeout=30)

During handling of the above exception, another exception occurred:

Traceback (most recent call last):
  File ".\crazy_functions\crazy_utils.py", line 201, in _req_gpt
    gpt_say = predict_no_ui_long_connection(
              ^^^^^^^^^^^^^^^^^^^^^^^^^^^^^^
  File ".\request_llm\bridge_all.py", line 173, in predict_no_ui_long_connection
    return method(inputs, llm_kwargs, history, sys_prompt, observe_window, console_slience)
           ^^^^^^^^^^^^^^^^^^^^^^^^^^^^^^^^^^^^^^^^^^^^^^^^^^^^^^^^^^^^^^^^^^^^^^^^^^^^^^^^
  File ".\request_llm\bridge_chatgpt.py", line 70, in predict_no_ui_long_connection
    if retry > MAX_RETRY: raise TimeoutError
                          ^^^^^^^^^^^^^^^^^^
TimeoutError
```

[Local Message] 警告，线程7在执行过程中遭遇问题, Traceback：

```
Traceback (most recent call last):
  File ".\crazy_functions\crazy_utils.py", line 201, in _req_gpt
    gpt_say = predict_no_ui_long_connection(
              ^^^^^^^^^^^^^^^^^^^^^^^^^^^^^^
  File ".\request_llm\bridge_all.py", line 173, in predict_no_ui_long_connection
    return method(inputs, llm_kwargs, history, sys_prompt, observe_window, console_slience)
           ^^^^^^^^^^^^^^^^^^^^^^^^^^^^^^^^^^^^^^^^^^^^^^^^^^^^^^^^^^^^^^^^^^^^^^^^^^^^^^^^
  File ".\request_llm\bridge_chatgpt.py", line 87, in predict_no_ui_long_connection
    raise RuntimeError("OpenAI拒绝了请求：" + error_msg)
RuntimeError: OpenAI拒绝了请求：{    "error": {        "message": "You exceeded your current quota, please check your plan and billing details.",        "type": "insufficient_quota",        "param": null,        "code": null    }}
```



## [8/10] 请对下面的程序文件做一个概述: D:\MOSS\models\quantization.py

[Local Message] 警告，线程8在执行过程中遭遇问题, Traceback：

```
Traceback (most recent call last):
  File ".\crazy_functions\crazy_utils.py", line 201, in _req_gpt
    gpt_say = predict_no_ui_long_connection(
              ^^^^^^^^^^^^^^^^^^^^^^^^^^^^^^
  File ".\request_llm\bridge_all.py", line 173, in predict_no_ui_long_connection
    return method(inputs, llm_kwargs, history, sys_prompt, observe_window, console_slience)
           ^^^^^^^^^^^^^^^^^^^^^^^^^^^^^^^^^^^^^^^^^^^^^^^^^^^^^^^^^^^^^^^^^^^^^^^^^^^^^^^^
  File ".\request_llm\bridge_chatgpt.py", line 87, in predict_no_ui_long_connection
    raise RuntimeError("OpenAI拒绝了请求：" + error_msg)
RuntimeError: OpenAI拒绝了请求：{    "error": {        "message": "Rate limit reached for default-gpt-3.5-turbo in organization org-AuKGyhKmlQ3EbEATMDtOoiNY on requests per min. Limit: 3 / min. Please try again in 20s. Contact support@openai.com if you continue to have issues. Please add a payment method to your account to increase your rate limit. Visit https://platform.openai.com/account/billing to add a payment method.",        "type": "requests",        "param": null,        "code": null    }}
```

[Local Message] 警告，线程8在执行过程中遭遇问题, Traceback：

```
Traceback (most recent call last):
  File ".\crazy_functions\crazy_utils.py", line 201, in _req_gpt
    gpt_say = predict_no_ui_long_connection(
              ^^^^^^^^^^^^^^^^^^^^^^^^^^^^^^
  File ".\request_llm\bridge_all.py", line 173, in predict_no_ui_long_connection
    return method(inputs, llm_kwargs, history, sys_prompt, observe_window, console_slience)
           ^^^^^^^^^^^^^^^^^^^^^^^^^^^^^^^^^^^^^^^^^^^^^^^^^^^^^^^^^^^^^^^^^^^^^^^^^^^^^^^^
  File ".\request_llm\bridge_chatgpt.py", line 87, in predict_no_ui_long_connection
    raise RuntimeError("OpenAI拒绝了请求：" + error_msg)
RuntimeError: OpenAI拒绝了请求：{    "error": {        "message": "You exceeded your current quota, please check your plan and billing details.",        "type": "insufficient_quota",        "param": null,        "code": null    }}
```

[Local Message] 警告，线程8在执行过程中遭遇问题, Traceback：

```
Traceback (most recent call last):
  File ".\crazy_functions\crazy_utils.py", line 201, in _req_gpt
    gpt_say = predict_no_ui_long_connection(
              ^^^^^^^^^^^^^^^^^^^^^^^^^^^^^^
  File ".\request_llm\bridge_all.py", line 173, in predict_no_ui_long_connection
    return method(inputs, llm_kwargs, history, sys_prompt, observe_window, console_slience)
           ^^^^^^^^^^^^^^^^^^^^^^^^^^^^^^^^^^^^^^^^^^^^^^^^^^^^^^^^^^^^^^^^^^^^^^^^^^^^^^^^
  File ".\request_llm\bridge_chatgpt.py", line 87, in predict_no_ui_long_connection
    raise RuntimeError("OpenAI拒绝了请求：" + error_msg)
RuntimeError: OpenAI拒绝了请求：{    "error": {        "message": "You exceeded your current quota, please check your plan and billing details.",        "type": "insufficient_quota",        "param": null,        "code": null    }}
```



## [9/10] 请对下面的程序文件做一个概述: D:\MOSS\models\tokenization_moss.py

[Local Message] 警告，线程9在执行过程中遭遇问题, Traceback：

```
Traceback (most recent call last):
  File ".\crazy_functions\crazy_utils.py", line 201, in _req_gpt
    gpt_say = predict_no_ui_long_connection(
              ^^^^^^^^^^^^^^^^^^^^^^^^^^^^^^
  File ".\request_llm\bridge_all.py", line 173, in predict_no_ui_long_connection
    return method(inputs, llm_kwargs, history, sys_prompt, observe_window, console_slience)
           ^^^^^^^^^^^^^^^^^^^^^^^^^^^^^^^^^^^^^^^^^^^^^^^^^^^^^^^^^^^^^^^^^^^^^^^^^^^^^^^^
  File ".\request_llm\bridge_chatgpt.py", line 87, in predict_no_ui_long_connection
    raise RuntimeError("OpenAI拒绝了请求：" + error_msg)
RuntimeError: OpenAI拒绝了请求：{    "error": {        "message": "You exceeded your current quota, please check your plan and billing details.",        "type": "insufficient_quota",        "param": null,        "code": null    }}
```

[Local Message] 警告，线程9在执行过程中遭遇问题, Traceback：

```
Traceback (most recent call last):
  File ".\crazy_functions\crazy_utils.py", line 201, in _req_gpt
    gpt_say = predict_no_ui_long_connection(
              ^^^^^^^^^^^^^^^^^^^^^^^^^^^^^^
  File ".\request_llm\bridge_all.py", line 173, in predict_no_ui_long_connection
    return method(inputs, llm_kwargs, history, sys_prompt, observe_window, console_slience)
           ^^^^^^^^^^^^^^^^^^^^^^^^^^^^^^^^^^^^^^^^^^^^^^^^^^^^^^^^^^^^^^^^^^^^^^^^^^^^^^^^
  File ".\request_llm\bridge_chatgpt.py", line 87, in predict_no_ui_long_connection
    raise RuntimeError("OpenAI拒绝了请求：" + error_msg)
RuntimeError: OpenAI拒绝了请求：{    "error": {        "message": "You exceeded your current quota, please check your plan and billing details.",        "type": "insufficient_quota",        "param": null,        "code": null    }}
```

[Local Message] 警告，线程9在执行过程中遭遇问题, Traceback：

```
Traceback (most recent call last):
  File ".\crazy_functions\crazy_utils.py", line 201, in _req_gpt
    gpt_say = predict_no_ui_long_connection(
              ^^^^^^^^^^^^^^^^^^^^^^^^^^^^^^
  File ".\request_llm\bridge_all.py", line 173, in predict_no_ui_long_connection
    return method(inputs, llm_kwargs, history, sys_prompt, observe_window, console_slience)
           ^^^^^^^^^^^^^^^^^^^^^^^^^^^^^^^^^^^^^^^^^^^^^^^^^^^^^^^^^^^^^^^^^^^^^^^^^^^^^^^^
  File ".\request_llm\bridge_chatgpt.py", line 87, in predict_no_ui_long_connection
    raise RuntimeError("OpenAI拒绝了请求：" + error_msg)
RuntimeError: OpenAI拒绝了请求：{    "error": {        "message": "You exceeded your current quota, please check your plan and billing details.",        "type": "insufficient_quota",        "param": null,        "code": null    }}
```



## 用一张Markdown表格简要描述以下文件的功能：finetune_moss.py, moss_cli_demo.py, moss_gui_demo.py, moss_inference.py, utils.py, models\configuration_moss.py, models\custom_autotune.py, models\modeling_moss.py, models\quantization.py, models\tokenization_moss.py。根据以上分析，用一句话概括程序的整体功能。

[Local Message] 警告，在执行过程中遭遇问题, Traceback：

```
Traceback (most recent call last):
  File ".\crazy_functions\crazy_utils.py", line 78, in _req_gpt
    result = predict_no_ui_long_connection(
             ^^^^^^^^^^^^^^^^^^^^^^^^^^^^^^
  File ".\request_llm\bridge_all.py", line 173, in predict_no_ui_long_connection
    return method(inputs, llm_kwargs, history, sys_prompt, observe_window, console_slience)
           ^^^^^^^^^^^^^^^^^^^^^^^^^^^^^^^^^^^^^^^^^^^^^^^^^^^^^^^^^^^^^^^^^^^^^^^^^^^^^^^^
  File ".\request_llm\bridge_chatgpt.py", line 87, in predict_no_ui_long_connection
    raise RuntimeError("OpenAI拒绝了请求：" + error_msg)
RuntimeError: OpenAI拒绝了请求：{    "error": {        "message": "You exceeded your current quota, please check your plan and billing details.",        "type": "insufficient_quota",        "param": null,        "code": null    }}
```

[Local Message] 重试中，请稍等 1/2：

[Local Message] 警告，在执行过程中遭遇问题, Traceback：

```
Traceback (most recent call last):
  File ".\crazy_functions\crazy_utils.py", line 78, in _req_gpt
    result = predict_no_ui_long_connection(
             ^^^^^^^^^^^^^^^^^^^^^^^^^^^^^^
  File ".\request_llm\bridge_all.py", line 173, in predict_no_ui_long_connection
    return method(inputs, llm_kwargs, history, sys_prompt, observe_window, console_slience)
           ^^^^^^^^^^^^^^^^^^^^^^^^^^^^^^^^^^^^^^^^^^^^^^^^^^^^^^^^^^^^^^^^^^^^^^^^^^^^^^^^
  File ".\request_llm\bridge_chatgpt.py", line 87, in predict_no_ui_long_connection
    raise RuntimeError("OpenAI拒绝了请求：" + error_msg)
RuntimeError: OpenAI拒绝了请求：{    "error": {        "message": "You exceeded your current quota, please check your plan and billing details.",        "type": "insufficient_quota",        "param": null,        "code": null    }}
```

[Local Message] 重试中，请稍等 2/2：

[Local Message] 警告，在执行过程中遭遇问题, Traceback：

```
Traceback (most recent call last):
  File ".\crazy_functions\crazy_utils.py", line 78, in _req_gpt
    result = predict_no_ui_long_connection(
             ^^^^^^^^^^^^^^^^^^^^^^^^^^^^^^
  File ".\request_llm\bridge_all.py", line 173, in predict_no_ui_long_connection
    return method(inputs, llm_kwargs, history, sys_prompt, observe_window, console_slience)
           ^^^^^^^^^^^^^^^^^^^^^^^^^^^^^^^^^^^^^^^^^^^^^^^^^^^^^^^^^^^^^^^^^^^^^^^^^^^^^^^^
  File ".\request_llm\bridge_chatgpt.py", line 87, in predict_no_ui_long_connection
    raise RuntimeError("OpenAI拒绝了请求：" + error_msg)
RuntimeError: OpenAI拒绝了请求：{    "error": {        "message": "You exceeded your current quota, please check your plan and billing details.",        "type": "insufficient_quota",        "param": null,        "code": null    }}
```



